<mujoco model="tool">
  <compiler angle="degree" coordinate="global" inertiafromgeom="true"/>
  <default>
    <!-- <joint armature="1" damping="1" limited="true"/> -->
    <geom conaffinity="1" condim="1" contype="1" margin="0.001" rgba=".98 .54 .56 1." solimp=".8 .8 .01" solref=".02 1"/>
    <motor ctrllimited="true" ctrlrange="-.4 .4"/>
  </default>
  <option integrator="RK4" timestep="0.002"/>
  <visual>
    <headlight ambient=".1 .1 .1" diffuse=".6 .6 .6" specular="0.3 0.3 0.3"/>
    <map znear=".01"/>
    <quality shadowsize="16384"/>
  </visual>
  <worldbody>
    <light cutoff="100" diffuse="1 1 1" dir="-1 0 -1.3" directional="true" exponent="1" pos="1 0 1.3" specular=".1 .1 .1" castshadow="true"/>
    <geom conaffinity="1" condim="3" name="floor" pos="0 0 0" rgba="0.8 0.9 0.8 1" size="200 200 .125" type="plane" material="grid_new"/>
    
    <body name="0" pos="0.4 0 1.0">
      <camera name="track" mode="trackcom" pos="0 -3 1" xyaxes="1 0 0 0 0 1"/>
      <joint armature="0" axis="0 0 1" damping="0" limited="false" name="0_joint" pos="0 0 0" stiffness="0" type="hinge"/>
      <geom friction="0.9" fromto="0 0 0 0.8 0 0" size="0.05" type="capsule"/>
      <body name="1" pos="1.0 0 0">
        <joint axis="0 0 1" name="1_joint" pos="0.8 0 0" range="-360 360" type="hinge"/>
        <geom friction="0.9" fromto="0.8 0 0 1.2 0 0" size="0.05" type="capsule"/>
        <body name="2" pos="1.4 0 0">
          <joint axis="0 0 1" name="2_joint" pos="1.2 0 0" range="-360 360" type="hinge"/>
          <geom friction="0.9" fromto="1.2 0 0 1.6 0 0" size="0.05" type="capsule"/>
        </body>
      </body>
    </body>
    
    <body name="obj_0" pos="0.5 0.5 0.05">
        <joint  name="3_joint" type="free" damping="0.01" pos="0 0 0" />
        <geom friction="0.9" size="0.1" type="sphere" pos="0.5 0.5 0.05" rgba="0.0 1.0 0.0 1.0" mass="0.5"/>
    </body>
  </worldbody>
  <actuator>
    <motor ctrllimited="true" ctrlrange="-50.0 50.0" gear="500" joint="0_joint" name="0_joint"/>
    <motor ctrllimited="true" ctrlrange="-5.0 5.0" gear="500" joint="1_joint" name="1_joint"/>
    <motor ctrllimited="true" ctrlrange="-1.0 1.0" gear="500" joint="2_joint" name="2_joint"/>
    
  </actuator>
  <asset>
    <texture type="skybox" builtin="gradient" rgb1=".4 .5 .6" rgb2="0 0 0" width="100" height="100"/>
    <texture builtin="flat" height="1278" mark="cross" markrgb="1 1 1" name="texgeom" random="0.01" rgb1="0.8 0.6 0.4" rgb2="0.8 0.6 0.4" type="cube" width="127"/>
    <texture builtin="checker" height="100" name="texplane" rgb1="0 0 0" rgb2="0.8 0.8 0.8" type="2d" width="100"/>
    <material name="MatPlane" reflectance="0.5" shininess="1" specular="1" texrepeat="60 60" texture="texplane"/>
    <material name="geom" texture="texgeom" texuniform="true"/>
    <texture name="grid_new" type="2d" builtin="checker" rgb1=".1 .3 .2" rgb2=".2 .4 .3" width="1000" height="1000" mark="none" markrgb=".8 .6 .4"/>
    <material name="grid_new" texture="grid_new" texrepeat="0.2 0.2" texuniform="true" reflectance=".2"/>
  </asset>
</mujoco>
